Workbook
Name Slicer_Department: #N/A
Name Slicer_Employment_Status: #N/A
Name Slicer_Performace_Band: #N/A

Sheet HR Dashboard
AC8: s

Sheet Analysis
A5: Headcount and Salary per Department | F5: Rate of Attrition per Department | K5: Bonus Payout per Performance Band
A6: Departments | B6: Count of Employees | C6: Average of Salary | F6: Departments | G6: Count of Employee ID
A7: Information Technology | B7: 34 | C7: 78738.441 | F7: Finance | G7: 0.12142857 | K7: Performance Band | L7: Sum of Bonus Payout
A8: Sales | B8: 29 | C8: 82899.138 | F8: Human Resources | G8: 0.12142857 | K8: Exceeding | L8: 1316600.8
A9: Operations | B9: 24 | C9: 75290.417 | F9: Information Technology | G9: 0.24285714 | K9: Achieving | L9: 160371.4
A10: Marketing | B10: 19 | C10: 84821.263 | F10: Marketing | G10: 0.13571429 | K10: Outstanding | L10: 91073.88
A11: Human Resources | B11: 17 | C11: 86878.765 | F11: Operations | G11: 0.17142857 | K11: Developing | L11: 69012.42
A12: Finance | B12: 17 | C12: 85206.471 | F12: Sales | G12: 0.20714286 | K12: Needs Improvement | L12: 0
A13: Grand Total | B13: 140 | C13: 81608.607 | F13: Grand Total | G13: 1 | K13: Grand Total | L13: 1637058.5
A31: Performance by Status
A32: Employment Status | B32: Average of Performance Score | L32: Count of Employee ID
A33: Active | B33: 67.577586 | J33: Sum of Salary | L33: 140
A34: Left | B34: 67.25 | F34: KEY PERFORMANCE INDICATORS | J34: 11425205
A35: Grand Total | B35: 67.521429
F36: AVERAGE SALARY | G36: 82117.673
F38: SUM OF BONUS PAID | G38: 1895807.6
F40: HIGEST RATE OF ATTRITION | G40: 0.24
F42: TOTAL SALARY PAID | G42: 12317651
F44: NUMBERS OF EMPLOYEES | G44: 150

Sheet Cleaned Employee Dataset
B1: Employee ID | C1: Full Name | D1: Department | E1: Dept Code | F1: Hire Date | G1: Years of Service | H1: Salary | I1: Performance Score | J1: Employment Status | K1: Performace Band | L1: Bonus Percentage | M1: Bonus Payout | N1: Actual Pay
B2: EMP050 | C2: William Gonzalez | D2: =VLOOKUP(Cleaned[[#This Row],[Dept Code]], Lookup_Departments!$A$2:$B$7, 2,FALSE) -> Sales | E2: SAL05 | F2: 42008 | G2: =DATEDIF(Cleaned[[#This Row],[Hire Date]], TODAY(), "Y")& "Years" -> 11Years | H2: 115288 | I2: 61 | J2: Active | K2: {=_xlfn.IFS(I2<=49,"Needs Improvement", I2<=69, "Developing", I2<=84, "Achieving", I2<=94, "Exceeding", I2>94, "Outstanding")} -> Developing | L2: {=_xlfn.IFS(K2="Needs Improvement", 0, K2="Developing", 0.02, K2= "Achieving", 0.05, K2="Exceeding",0.8, K2="Outstanding", 0.12)} -> 0.02 | M2: =Cleaned[[#This Row],[Salary]]*Cleaned[[#This Row],[Bonus Percentage]] -> 2305.76 | N2: =Cleaned[[#This Row],[Salary]]+Cleaned[[#This Row],[Bonus Payout]] -> 117593.76
B3: EMP047 | C3: Jane Lopez | D3: =VLOOKUP(Cleaned[[#This Row],[Dept Code]], Lookup_Departments!$A$2:$B$7, 2,FALSE) -> Marketing | E3: MKT04 | F3: 42074 | G3: =DATEDIF(Cleaned[[#This Row],[Hire Date]], TODAY(), "Y")& "Years" -> 11Years | H3: 101750 | I3: 84 | J3: Left | K3: {=_xlfn.IFS(I3<=49,"Needs Improvement", I3<=69, "Developing", I3<=84, "Achieving", I3<=94, "Exceeding", I3>94, "Outstanding")} -> Achieving | L3: {=_xlfn.IFS(K3="Needs Improvement", 0, K3="Developing", 0.02, K3= "Achieving", 0.05, K3="Exceeding",0.8, K3="Outstanding", 0.12)} -> 0.05 | M3: =Cleaned[[#This Row],[Salary]]*Cleaned[[#This Row],[Bonus Percentage]] -> 5087.5 | N3: =Cleaned[[#This Row],[Salary]]+Cleaned[[#This Row],[Bonus Payout]] -> 106837.5
B4: EMP123 | C4: Robert Miller | D4: =VLOOKUP(Cleaned[[#This Row],[Dept Code]], Lookup_Departments!$A$2:$B$7, 2,FALSE) -> Information Technology | E4: IT02 | F4: 42122 | G4: =DATEDIF(Cleaned[[#This Row],[Hire Date]], TODAY(), "Y")& "Years" -> 11Years | H4: 75519 | I4: 64 | J4: Active | K4: {=_xlfn.IFS(I4<=49,"Needs Improvement", I4<=69, "Developing", I4<=84, "Achieving", I4<=94, "Exceeding", I4>94, "Outstanding")} -> Developing | L4: {=_xlfn.IFS(K4="Needs Improvement", 0, K4="Developing", 0.02, K4= "Achieving", 0.05, K4="Exceeding",0.8, K4="Outstanding", 0.12)} -> 0.02 | M4: =Cleaned[[#This Row],[Salary]]*Cleaned[[#This Row],[Bonus Percentage]] -> 1510.38 | N4: =Cleaned[[#This Row],[Salary]]+Cleaned[[#This Row],[Bonus Payout]] -> 77029.38
B5: EMP100 | C5: Melissa Hernandez | D5: =VLOOKUP(Cleaned[[#This Row],[Dept Code]], Lookup_Departments!$A$2:$B$7, 2,FALSE) -> Sales | E5: SAL05 | F5: 42175 | G5: =DATEDIF(Cleaned[[#This Row],[Hire Date]], TODAY(), "Y")& "Years" -> 11Years | H5: 72457 | I5: 94 | J5: Resigned | K5: {=_xlfn.IFS(I5<=49,"Needs Improvement", I5<=69, "Developing", I5<=84, "Achieving", I5<=94, "Exceeding", I5>94, "Outstanding")} -> Exceeding | L5: {=_xlfn.IFS(K5="Needs Improvement", 0, K5="Developing", 0.02, K5= "Achieving", 0.05, K5="Exceeding",0.8, K5="Outstanding", 0.12)} -> 0.8 | M5: =Cleaned[[#This Row],[Salary]]*Cleaned[[#This Row],[Bonus Percentage]] -> 57965.6 | N5: =Cleaned[[#This Row],[Salary]]+Cleaned[[#This Row],[Bonus Payout]] -> 130422.6
B6: EMP083 | C6: William Garcia | D6: =VLOOKUP(Cleaned[[#This Row],[Dept Code]], Lookup_Departments!$A$2:$B$7, 2,FALSE) -> Sales | E6: SAL05 | F6: 42192 | G6: =DATEDIF(Cleaned[[#This Row],[Hire Date]], TODAY(), "Y")& "Years" -> 10Years | H6: 65235 | I6: 97 | J6: Active | K6: {=_xlfn.IFS(I6<=49,"Needs Improvement", I6<=69, "Developing", I6<=84, "Achieving", I6<=94, "Exceeding", I6>94, "Outstanding")} -> Outstanding | L6: {=_xlfn.IFS(K6="Needs Improvement", 0, K6="Developing", 0.02, K6= "Achieving", 0.05, K6="Exceeding",0.8, K6="Outstanding", 0.12)} -> 0.12 | M6: =Cleaned[[#This Row],[Salary]]*Cleaned[[#This Row],[Bonus Percentage]] -> 7828.2 | N6: =Cleaned[[#This Row],[Salary]]+Cleaned[[#This Row],[Bonus Payout]] -> 73063.2 | W6: =TODAY() -> 46209
B7: EMP015 | C7: John Rodriguez | D7: =VLOOKUP(Cleaned[[#This Row],[Dept Code]], Lookup_Departments!$A$2:$B$7, 2,FALSE) -> Sales | E7: SAL05 | F7: 42202 | G7: =DATEDIF(Cleaned[[#This Row],[Hire Date]], TODAY(), "Y")& "Years" -> 10Years | H7: 72457 | I7: 68 | J7: Active | K7: {=_xlfn.IFS(I7<=49,"Needs Improvement", I7<=69, "Developing", I7<=84, "Achieving", I7<=94, "Exceeding", I7>94, "Outstanding")} -> Developing | L7: {=_xlfn.IFS(K7="Needs Improvement", 0, K7="Developing", 0.02, K7= "Achieving", 0.05, K7="Exceeding",0.8, K7="Outstanding", 0.12)} -> 0.02 | M7: =Cleaned[[#This Row],[Salary]]*Cleaned[[#This Row],[Bonus Percentage]] -> 1449.14 | N7: =Cleaned[[#This Row],[Salary]]+Cleaned[[#This Row],[Bonus Payout]] -> 73906.14
B8: EMP076 | C8: Thomas Hernandez | D8: =VLOOKUP(Cleaned[[#This Row],[Dept Code]], Lookup_Departments!$A$2:$B$7, 2,FALSE) -> Operations | E8: OPS06 | F8: 42221 | G8: =DATEDIF(Cleaned[[#This Row],[Hire Date]], TODAY(), "Y")& "Years" -> 10Years | H8: 97055 | I8: 80 | J8: Active | K8: {=_xlfn.IFS(I8<=49,"Needs Improvement", I8<=69, "Developing", I8<=84, "Achieving", I8<=94, "Exceeding", I8>94, "Outstanding")} -> Achieving | L8: {=_xlfn.IFS(K8="Needs Improvement", 0, K8="Developing", 0.02, K8= "Achieving", 0.05, K8="Exceeding",0.8, K8="Outstanding", 0.12)} -> 0.05 | M8: =Cleaned[[#This Row],[Salary]]*Cleaned[[#This Row],[Bonus Percentage]] -> 4852.75 | N8: =Cleaned[[#This Row],[Salary]]+Cleaned[[#This Row],[Bonus Payout]] -> 101907.75
B9: EMP106 | C9: A Brown | D9: =VLOOKUP(Cleaned[[#This Row],[Dept Code]], Lookup_Departments!$A$2:$B$7, 2,FALSE) -> Information Technology | E9: IT02 | F9: 42248 | G9: =DATEDIF(Cleaned[[#This Row],[Hire Date]], TODAY(), "Y")& "Years" -> 10Years | H9: 102691 | I9: 52 | J9: Active | K9: {=_xlfn.IFS(I9<=49,"Needs Improvement", I9<=69, "Developing", I9<=84, "Achieving", I9<=94, "Exceeding", I9>94, "Outstanding")} -> Developing | L9: {=_xlfn.IFS(K9="Needs Improvement", 0, K9="Developing", 0.02, K9= "Achieving", 0.05, K9="Exceeding",0.8, K9="Outstanding", 0.12)} -> 0.02 | M9: =Cleaned[[#This Row],[Salary]]*Cleaned[[#This Row],[Bonus Percentage]] -> 2053.82 | N9: =Cleaned[[#This Row],[Salary]]+Cleaned[[#This Row],[Bonus Payout]] -> 104744.82
B10: EMP026 | C10: Jane Gonzalez | D10: =VLOOKUP(Cleaned[[#This Row],[Dept Code]], Lookup_Departments!$A$2:$B$7, 2,FALSE) -> Sales | E10: SAL05 | F10: 42249 | G10: =DATEDIF(Cleaned[[#This Row],[Hire Date]], TODAY(), "Y")& "Years" -> 10Years | H10: 72457 | I10: 67 | J10: Active | K10: {=_xlfn.IFS(I10<=49,"Needs Improvement", I10<=69, "Developing", I10<=84, "Achieving", I10<=94, "Exceeding", I10>94, "Outstanding")} -> Developing | L10: {=_xlfn.IFS(K10="Needs Improvement", 0, K10="Developing", 0.02, K10= "Achieving", 0.05, K10="Exceeding",0.8, K10="Outstanding", 0.12)} -> 0.02 | M10: =Cleaned[[#This Row],[Salary]]*Cleaned[[#This Row],[Bonus Percentage]] -> 1449.14 | N10: =Cleaned[[#This Row],[Salary]]+Cleaned[[#This Row],[Bonus Payout]] -> 73906.14
B11: EMP053 | C11: Richard Williams | D11: =VLOOKUP(Cleaned[[#This Row],[Dept Code]], Lookup_Departments!$A$2:$B$7, 2,FALSE) -> Finance | E11: FIN03 | F11: 42299 | G11: =DATEDIF(Cleaned[[#This Row],[Hire Date]], TODAY(), "Y")& "Years" -> 10Years | H11: 72457 | I11: 62 | J11: Active | K11: {=_xlfn.IFS(I11<=49,"Needs Improvement", I11<=69, "Developing", I11<=84, "Achieving", I11<=94, "Exceeding", I11>94, "Outstanding")} -> Developing | L11: {=_xlfn.IFS(K11="Needs Improvement", 0, K11="Developing", 0.02, K11= "Achieving", 0.05, K11="Exceeding",0.8, K11="Outstanding", 0.12)} -> 0.02 | M11: =Cleaned[[#This Row],[Salary]]*Cleaned[[#This Row],[Bonus Percentage]] -> 1449.14 | N11: =Cleaned[[#This Row],[Salary]]+Cleaned[[#This Row],[Bonus Payout]] -> 73906.14
B12: EMP006 | C12: Jessica Anderson | D12: =VLOOKUP(Cleaned[[#This Row],[Dept Code]], Lookup_Departments!$A$2:$B$7, 2,FALSE) -> Human Resources | E12: HR01 | F12: 42304 | G12: =DATEDIF(Cleaned[[#This Row],[Hire Date]], TODAY(), "Y")& "Years" -> 10Years | H12: 56073 | I12: 79 | J12: Active | K12: {=_xlfn.IFS(I12<=49,"Needs Improvement", I12<=69, "Developing", I12<=84, "Achieving", I12<=94, "Exceeding", I12>94, "Outstanding")} -> Achieving | L12: {=_xlfn.IFS(K12="Needs Improvement", 0, K12="Developing", 0.02, K12= "Achieving", 0.05, K12="Exceeding",0.8, K12="Outstanding", 0.12)} -> 0.05 | M12: =Cleaned[[#This Row],[Salary]]*Cleaned[[#This Row],[Bonus Percentage]] -> 2803.65 | N12: =Cleaned[[#This Row],[Salary]]+Cleaned[[#This Row],[Bonus Payout]] -> 58876.65
B13: EMP132 | C13: Jessica Garcia | D13: =VLOOKUP(Cleaned[[#This Row],[Dept Code]], Lookup_Departments!$A$2:$B$7, 2,FALSE) -> Operations | E13: OPS06 | F13: 42330 | G13: =DATEDIF(Cleaned[[#This Row],[Hire Date]], TODAY(), "Y")& "Years" -> 10Years | H13: 86480 | I13: 75 | J13: Active | K13: {=_xlfn.IFS(I13<=49,"Needs Improvement", I13<=69, "Developing", I13<=84, "Achieving", I13<=94, "Exceeding", I13>94, "Outstanding")} -> Achieving | L13: {=_xlfn.IFS(K13="Needs Improvement", 0, K13="Developing", 0.02, K13= "Achieving", 0.05, K13="Exceeding",0.8, K13="Outstanding", 0.12)} -> 0.05 | M13: =Cleaned[[#This Row],[Salary]]*Cleaned[[#This Row],[Bonus Percentage]] -> 4324 | N13: =Cleaned[[#This Row],[Salary]]+Cleaned[[#This Row],[Bonus Payout]] -> 90804
B14: EMP126 | C14: Emily Davis | D14: =VLOOKUP(Cleaned[[#This Row],[Dept Code]], Lookup_Departments!$A$2:$B$7, 2,FALSE) -> Information Technology | E14: IT02 | F14: 42337 | G14: =DATEDIF(Cleaned[[#This Row],[Hire Date]], TODAY(), "Y")& "Years" -> 10Years | H14: 105765 | I14: 42 | J14: Active | K14: {=_xlfn.IFS(I14<=49,"Needs Improvement", I14<=69, "Developing", I14<=84, "Achieving", I14<=94, "Exceeding", I14>94, "Outstanding")} -> Needs Improvement | L14: {=_xlfn.IFS(K14="Needs Improvement", 0, K14="Developing", 0.02, K14= "Achieving", 0.05, K14="Exceeding",0.8, K14="Outstanding", 0.12)} -> 0 | M14: =Cleaned[[#This Row],[Salary]]*Cleaned[[#This Row],[Bonus Percentage]] -> 0 | N14: =Cleaned[[#This Row],[Salary]]+Cleaned[[#This Row],[Bonus Payout]] -> 105765
B15: EMP057 | C15: Emily Hernandez | D15: =VLOOKUP(Cleaned[[#This Row],[Dept Code]], Lookup_Departments!$A$2:$B$7, 2,FALSE) -> Information Technology | E15: IT02 | F15: 42425 | G15: =DATEDIF(Cleaned[[#This Row],[Hire Date]], TODAY(), "Y")& "Years" -> 10Years | H15: 76918 | I15: 62 | J15: Active | K15: {=_xlfn.IFS(I15<=49,"Needs Improvement", I15<=69, "Developing", I15<=84, "Achieving", I15<=94, "Exceeding", I15>94, "Outstanding")} -> Developing | L15: {=_xlfn.IFS(K15="Needs Improvement", 0, K15="Developing", 0.02, K15= "Achieving", 0.05, K15="Exceeding",0.8, K15="Outstanding", 0.12)} -> 0.02 | M15: =Cleaned[[#This Row],[Salary]]*Cleaned[[#This Row],[Bonus Percentage]] -> 1538.36 | N15: =Cleaned[[#This Row],[Salary]]+Cleaned[[#This Row],[Bonus Payout]] -> 78456.36
B16: EMP134 | C16: Emily Gonzalez | D16: =VLOOKUP(Cleaned[[#This Row],[Dept Code]], Lookup_Departments!$A$2:$B$7, 2,FALSE) -> Information Technology | E16: IT02 | F16: 42431 | G16: =DATEDIF(Cleaned[[#This Row],[Hire Date]], TODAY(), "Y")& "Years" -> 10Years | H16: 114425 | I16: 54 | J16: Left | K16: {=_xlfn.IFS(I16<=49,"Needs Improvement", I16<=69, "Developing", I16<=84, "Achieving", I16<=94, "Exceeding", I16>94, "Outstanding")} -> Developing | L16: {=_xlfn.IFS(K16="Needs Improvement", 0, K16="Developing", 0.02, K16= "Achieving", 0.05, K16="Exceeding",0.8, K16="Outstanding", 0.12)} -> 0.02 | M16: =Cleaned[[#This Row],[Salary]]*Cleaned[[#This Row],[Bonus Percentage]] -> 2288.5 | N16: =Cleaned[[#This Row],[Salary]]+Cleaned[[#This Row],[Bonus Payout]] -> 116713.5
B17: EMP051 | C17: Jane Davis | D17: =VLOOKUP(Cleaned[[#This Row],[Dept Code]], Lookup_Departments!$A$2:$B$7, 2,FALSE) -> Finance | E17: FIN03 | F17: 42433 | G17: =DATEDIF(Cleaned[[#This Row],[Hire Date]], TODAY(), "Y")& "Years" -> 10Years | H17: 46390 | I17: 95 | J17: Active | K17: {=_xlfn.IFS(I17<=49,"Needs Improvement", I17<=69, "Developing", I17<=84, "Achieving", I17<=94, "Exceeding", I17>94, "Outstanding")} -> Outstanding | L17: {=_xlfn.IFS(K17="Needs Improvement", 0, K17="Developing", 0.02, K17= "Achieving", 0.05, K17="Exceeding",0.8, K17="Outstanding", 0.12)} -> 0.12 | M17: =Cleaned[[#This Row],[Salary]]*Cleaned[[#This Row],[Bonus Percentage]] -> 5566.8 | N17: =Cleaned[[#This Row],[Salary]]+Cleaned[[#This Row],[Bonus Payout]] -> 51956.8
B18: EMP092 | C18: Emily Johnson | D18: =VLOOKUP(Cleaned[[#This Row],[Dept Code]], Lookup_Departments!$A$2:$B$7, 2,FALSE) -> Operations | E18: OPS06 | F18: 42512 | G18: =DATEDIF(Cleaned[[#This Row],[Hire Date]], TODAY(), "Y")& "Years" -> 10Years | H18: 81167 | I18: 40 | J18: Active | K18: {=_xlfn.IFS(I18<=49,"Needs Improvement", I18<=69, "Developing", I18<=84, "Achieving", I18<=94, "Exceeding", I18>94, "Outstanding")} -> Needs Improvement | L18: {=_xlfn.IFS(K18="Needs Improvement", 0, K18="Developing", 0.02, K18= "Achieving", 0.05, K18="Exceeding",0.8, K18="Outstanding", 0.12)} -> 0 | M18: =Cleaned[[#This Row],[Salary]]*Cleaned[[#This Row],[Bonus Percentage]] -> 0 | N18: =Cleaned[[#This Row],[Salary]]+Cleaned[[#This Row],[Bonus Payout]] -> 81167
... B151: EMP096 | C151: John Wilson | D151: =VLOOKUP(Cleaned[[#This Row],[Dept Code]], Lookup_Departments!$A$2:$B$7, 2,FALSE) -> Operations | E151: OPS06 | F151: 45272 | G151: =DATEDIF(Cleaned[[#This Row],[Hire Date]], TODAY(), "Y")& "Years" -> 2Years | H151: 59980 | I151: 70 | J151: Left | K151: {=_xlfn.IFS(I151<=49,"Needs Improvement", I151<=69, "Developing", I151<=84, "Achieving", I151<=94, "Exceeding", I151>94, "Outstanding")} -> Achieving | L151: {=_xlfn.IFS(K151="Needs Improvement", 0, K151="Developing", 0.02, K151= "Achieving", 0.05, K151="Exceeding",0.8, K151="Outstanding", 0.12)} -> 0.05 | M151: =Cleaned[[#This Row],[Salary]]*Cleaned[[#This Row],[Bonus Percentage]] -> 2999 | N151: =Cleaned[[#This Row],[Salary]]+Cleaned[[#This Row],[Bonus Payout]] -> 62979
F157: average Salary | G157: 72457 | H157: =AVERAGE(Cleaned[Salary]) -> 82117.673

Sheet Lookup_Departments
A1: Dept_Code | B1: Department_Name
A2: HR01 | B2: Human Resources
A3: IT02 | B3: Information Technology
A4: FIN03 | B4: Finance
A5: MKT04 | B5: Marketing
A6: SAL05 | B6: Sales
A7: OPS06 | B7: Operations

Sheet Lookup_Performance
A1: Min_Score | B1: Max_Score | C1: Performance_Band | D1: Bonus_Percentage
A2: 0 | B2: 49 | C2: Needs Improvement | D2: 0
A3: 50 | B3: 69 | C3: Developing | D3: 0.02
A4: 70 | B4: 84 | C4: Achieving | D4: 0.05
A5: 85 | B5: 94 | C5: Exceeding | D5: 0.08
A6: 95 | B6: 100 | C6: Outstanding | D6: 0.12

Sheet Raw_Employee_Data
A1: Emp ID | B1: First_Name | C1: Last_Name | D1: Dept Code | E1: Hire Date | F1: Salary | G1: Perf_Score | H1: Employment Status
A2: EMP127 | B2: Emily | C2: Brown | D2: IT02 | E2: 43093 | F2: 50361 | G2: 52 | H2: active
A3: EMP046 | B3: Richard | C3: Hernandez | D3: MKT04 | E3: 44659 | F3: 112673 | H3: ACTIVE
A4: EMP134 | B4: Emily | C4: Gonzalez | D4: IT02 | E4: 42431 | F4: $114,425 | G4: 54 | H4: LEFT
A5: EMP139 | B5: John | C5: Martinez | D5: FIN03 | E5: 45110 | F5: 103831 | G5: 70 | H5: active
A6: EMP112 | B6: Thomas | C6: Smith | D6: IT02 | E6: 44977 | F6: 73785 | G6: 40 | H6: Left
A7: EMP030 | B7: Emily | C7: Johnson | D7: OPS06 | E7: 02-Mar-20 | F7: 115882 | G7: 49 | H7: ACTIVE
A8: EMP096 | B8: John | C8: Wilson | D8: OPS06 | E8: 45272 | F8: 59980 | G8: 70 | H8: Left
A9: EMP098 | B9: Jessica | C9: Smith | D9: OPS06 | E9: 44174 | F9: 68728 | G9: 45 | H9: ACTIVE
A10: EMP095 | C10: Rodriguez | D10: FIN03 | E10: 43107 | F10: 102139 | G10: 79 | H10: active
A11: EMP140 | B11: Michael | C11: Martinez | D11: SAL05 | E11: 42676 | F11: 94998 | G11: 58 | H11: Active
A12: EMP020 | B12: Emily | C12: Miller | D12: sal05 | E12: 43911 | F12: $118,635 | G12: 49 | H12: Active
A13: EMP057 | B13: Emily | C13: Hernandez | D13: IT02 | E13: 42425 | F13: 76918 | G13: 62 | H13: Actv
A14: EMP016 | B14: Jane | C14: Williams | D14: mkt04 | E14: 17-Jun-21 | F14: 61408 | G14: 48 | H14: ACTIVE
A15: EMP070 | B15: Jane | C15: Miller | D15: MKT04 | E15: 44001 | F15: 99990 | G15: 54 | H15: Actv
A16: EMP025 | B16: Robert | C16: Jones | D16: MKT04 | E16: 43820 | F16: 80385 | H16: active
A17: EMP031 | B17: Thomas | C17: Rodriguez | D17: SAL05 | E17: 45169 | F17: 65290 | G17: 77 | H17: active
A18: EMP126 | B18: Emily | C18: Davis | D18: IT02 | E18: 42337 | F18: 105765 | G18: 42 | H18: Active
A19: EMP109 | B19: James | C19: Martinez | D19: SAL05 | E19: 42899 | F19: 102921 | G19: 49 | H19: ACTIVE
A20: EMP057 | B20: Emily | C20: Hernandez | D20: IT02 | E20: 42425 | F20: 76918 | G20: 62 | H20: Actv
A21: EMP066 | B21: Ashley | C21: Lopez | D21: MKT04 | E21: 43235 | F21: 73984 | G21: 93 | H21: Actv
A22: EMP120 | B22: Amanda | C22: Gonzalez | D22: IT02 | E22: 42575 | G22: 75 | H22: Actv
A23: EMP019 | B23: Michael | C23: Hernandez | D23: FIN03 | E23: 43076 | F23: 118527 | G23: 50 | H23: Actv
A24: EMP013 | B24: Richard | C24: Hernandez | D24: MKT04 | E24: 44353 | F24: 107871 | G24: 88 | H24: active
A25: EMP010 | B25: Michael | C25: Rodriguez | D25: IT02 | E25: 44815 | F25: 93956 | G25: 50 | H25: LEFT
A26: EMP032 | B26: Jessica | C26: Johnson | D26: FIN03 | E26: 42565 | F26: 100851 | G26: 64 | H26: ACTIVE
A27: EMP082 | B27: Ashley | C27: Williams | D27: SAL05 | E27: 44728 | F27: 68655 | G27: 32 | H27: active
A28: EMP052 | C28: Williams | D28: SAL05 | E28: 45134 | F28: 81205 | G28: 59 | H28: Actv
A29: EMP129 | B29: John | C29: Wilson | D29: SAL05 | E29: 09/24/2019 | F29: $77,610 | G29: 88 | H29: Actv
A30: EMP146 | B30: Thomas | C30: Rodriguez | D30: it02 | E30: 44765 | F30: $50,873 | G30: 90 | H30: Active
A31: EMP099 | B31: Michael | C31: Wilson | D31: fin03 | E31: 13-May-18 | F31: 85312 | G31: 66 | H31: active
A32: EMP015 | B32: John | C32: Rodriguez | D32: SAL05 | E32: 42202 | G32: 68 | H32: active
A33: EMP076 | B33: Thomas | C33: Hernandez | D33: OPS06 | E33: 05-Aug-15 | F33: 97055 | G33: 80 | H33: Actv
A34: EMP137 | B34: Michael | C34: Johnson | D34: IT02 | E34: 45195 | F34: 66069 | G34: 72 | H34: Actv
A35: EMP056 | B35: Sarah | C35: Brown | D35: it02 | E35: 10-Jun-19 | F35: 90157 | G35: 58 | H35: active
A36: EMP125 | B36: Jane | C36: Martinez | D36: HR01 | E36: 44578 | F36: 59899 | G36: 78 | H36: Actv
A37: EMP085 | B37: Emily | C37: Jones | D37: FIN03 | E37: 03-Jul-17 | F37: 113389 | G37: 30 | H37: ACTIVE
A38: EMP106 | C38: Brown | D38: IT02 | E38: 01-Sep-15 | F38: 102691 | G38: 52 | H38: Active
A39: EMP043 | B39: John | C39: Wilson | D39: OPS06 | E39: 03-Aug-22 | F39: 111845 | G39: 98 | H39: active
A40: EMP068 | B40: Melissa | C40: Brown | D40: SAL05 | E40: 06/29/2022 | F40: 69219 | G40: 93 | H40: Actv
...
